Workbook

Sheet Sheet3
A1: Row Labels | B1: Count of Region
A2: East | B2: 275
A3: North | B3: 292
A4: South | B4: 299
A5: West | B5: 289
A6: (blank)
A7: Grand Total | B7: 1155
A21: Average of Revenue | B21: =AVERAGE(Raw_Data!D:D) -> 30435.807

Sheet Raw_Data
A1: Order_ID | B1: Product | C1: Region | D1: Revenue | E1: Date
A2: 1000 | B2: Monitor | C2: South | D2: 10205.1 | E2: 45506
A3: 1001 | B3: Laptop | C3: East | E3: 2024-09-14
A4: 1084 | B4: Laptop | C4: West | D4: 1416.91 | E4: 2024/12/10
A5: 1003 | B5: Laptop | C5: North | D5: 27908.13 | E5: 23-06-2024
A6: 1004 | B6: Tablet | C6: South | D6: 27579.46 | E6: 2024-09-30
A7: 1005 | B7: Mouse | C7: West | D7: 26969 | E7: 2024/09/20
A8: 1006 | B8: Tablet | C8: East | D8: 31684.01 | E8: 15-04-2024
A9: 1007 | B9: Mouse | C9: East | D9: 43909.05 | E9: 2024/09/27
A10: 1008 | C10: East | D10: 17009.59 | E10: 2024-02-22
A11: 1009 | B11: Tablet | C11: West | D11: 1922.55 | E11: 09-01-2024
A12: 1542 | B12: Keyboard | C12: North | D12: 46504.95 | E12: 2024-09-17
A13: 1011 | B13: Laptop | C13: North | D13: 22878.28 | E13: 2024-03-02
A14: 1012 | B14: Laptop | C14: North | D14: 43081.44 | E14: 13-09-2024
A15: 1013 | C15: West | D15: 26920.85 | E15: 2024/06/27
A16: 1014 | B16: Laptop | C16: West | D16: 15708.24 | E16: 24-08-2024
A17: 1015 | B17: Laptop | C17: East | D17: 37836.89 | E17: 2024-03-02
A18: 1016 | B18: Tablet | C18: South | D18: 48638.97 | E18: 2024-12-13
A19: 1017 | B19: Keyboard | D19: 18982.09 | E19: 16-07-2024
A20: 1018 | B20: Laptop | C20: North | D20: 20068.97 | E20: 05-04-2024
A21: 1019 | B21: Laptop | C21: North | D21: 43023.96 | E21: 2024/04/10
A22: 1020 | B22: Monitor | C22: East | D22: 17440.14 | E22: 2024-08-12
A23: 1021 | B23: Laptop | C23: South | D23: 5770.35 | E23: 2024/07/02
A24: 1022 | B24: Monitor | C24: East | D24: 32610.71 | E24: 27-08-2024
A25: 1023 | B25: Mouse | C25: West | D25: 13994.22 | E25: 11-12-2024
A26: 1024 | B26: Mouse | C26: North | D26: 56267.07 | E26: 2024-05-08
A27: 1025 | B27: Mouse | C27: East | D27: 11322.34 | E27: 21-04-2024
A28: 1026 | B28: Keyboard | C28: South | D28: 38352.99 | E28: 2024/01/09
A29: 1027 | B29: Keyboard | C29: North | D29: 53378.44 | E29: 2024/04/25
A30: 1028 | B30: Tablet | C30: East | E30: 08-04-2024
A31: 1029 | B31: Monitor | C31: South | D31: 11379.59 | E31: 2024/03/08
A32: 1030 | B32: Keyboard | C32: North | D32: 39799.16 | E32: 02-02-2024
A33: 1031 | B33: Monitor | C33: West | D33: 29717.79 | E33: 2024-09-20
A34: 1032 | B34: Monitor | C34: West | D34: 43624.67 | E34: 2024-05-26
A35: 1033 | B35: Keyboard | C35: South | D35: 53126.15 | E35: 20-08-2024
A36: 1034 | B36: Mouse | C36: North | D36: 19036.12 | E36: 09-06-2024
A37: 1035 | B37: Keyboard | C37: South | D37: 6733.41 | E37: 14-10-2024
A38: 1036 | B38: Keyboard | C38: South | D38: 9060.66 | E38: 02-09-2024
A39: 1037 | B39: Mouse | C39: South | D39: 31169.2 | E39: 08-11-2024
A40: 1038 | B40: Monitor | C40: East | D40: 2629.39 | E40: 2024/12/19
...

Sheet Cleaned_Data
A1: Order_ID | B1: Product | C1: Region | D1: Revenue | E1: Date
A2: 1000 | B2: =IF(TRIM(Raw_Data!B2)="","Unknown",PROPER(TRIM(Raw_Data!B2))) -> Monitor | C2: =IF(TRIM(Raw_Data!C2)="","South",TRIM(Raw_Data!C2)) -> South | D2: =IF(TRIM(Raw_Data!D2)="",30435.80739,Raw_Data!D2) -> 10205.1 | E2: =TEXT(Raw_Data!E2,"DD-MM-YYYY") -> 02-08-2024
A3: 1001 | B3: =IF(TRIM(Raw_Data!B3)="","Unknown",PROPER(TRIM(Raw_Data!B3))) -> Laptop | C3: =IF(TRIM(Raw_Data!C3)="","South",TRIM(Raw_Data!C3)) -> East | D3: =IF(TRIM(Raw_Data!D3)="",30435.80739,Raw_Data!D3) -> 30435.807 | E3: =TEXT(Raw_Data!E3,"DD-MM-YYYY") -> 14-09-2024
A4: 1084 | B4: =IF(TRIM(Raw_Data!B4)="","Unknown",PROPER(TRIM(Raw_Data!B4))) -> Laptop | C4: =IF(TRIM(Raw_Data!C4)="","South",TRIM(Raw_Data!C4)) -> West | D4: =IF(TRIM(Raw_Data!D4)="",30435.80739,Raw_Data!D4) -> 1416.91 | E4: =TEXT(Raw_Data!E4,"DD-MM-YYYY") -> 10-12-2024
A5: 1003 | B5: =IF(TRIM(Raw_Data!B5)="","Unknown",PROPER(TRIM(Raw_Data!B5))) -> Laptop | C5: =IF(TRIM(Raw_Data!C5)="","South",TRIM(Raw_Data!C5)) -> North | D5: =IF(TRIM(Raw_Data!D5)="",30435.80739,Raw_Data!D5) -> 27908.13 | E5: =TEXT(Raw_Data!E5,"DD-MM-YYYY") -> 23-06-2024
A6: 1004 | B6: =IF(TRIM(Raw_Data!B6)="","Unknown",PROPER(TRIM(Raw_Data!B6))) -> Tablet | C6: =IF(TRIM(Raw_Data!C6)="","South",TRIM(Raw_Data!C6)) -> South | D6: =IF(TRIM(Raw_Data!D6)="",30435.80739,Raw_Data!D6) -> 27579.46 | E6: =TEXT(Raw_Data!E6,"DD-MM-YYYY") -> 30-09-2024
A7: 1005 | B7: =IF(TRIM(Raw_Data!B7)="","Unknown",PROPER(TRIM(Raw_Data!B7))) -> Mouse | C7: =IF(TRIM(Raw_Data!C7)="","South",TRIM(Raw_Data!C7)) -> West | D7: =IF(TRIM(Raw_Data!D7)="",30435.80739,Raw_Data!D7) -> 26969 | E7: =TEXT(Raw_Data!E7,"DD-MM-YYYY") -> 20-09-2024
A8: 1006 | B8: =IF(TRIM(Raw_Data!B8)="","Unknown",PROPER(TRIM(Raw_Data!B8))) -> Tablet | C8: =IF(TRIM(Raw_Data!C8)="","South",TRIM(Raw_Data!C8)) -> East | D8: =IF(TRIM(Raw_Data!D8)="",30435.80739,Raw_Data!D8) -> 31684.01 | E8: =TEXT(Raw_Data!E8,"DD-MM-YYYY") -> 15-04-2024
A9: 1007 | B9: =IF(TRIM(Raw_Data!B9)="","Unknown",PROPER(TRIM(Raw_Data!B9))) -> Mouse | C9: =IF(TRIM(Raw_Data!C9)="","South",TRIM(Raw_Data!C9)) -> East | D9: =IF(TRIM(Raw_Data!D9)="",30435.80739,Raw_Data!D9) -> 43909.05 | E9: =TEXT(Raw_Data!E9,"DD-MM-YYYY") -> 27-09-2024
A10: 1008 | B10: =IF(TRIM(Raw_Data!B10)="","Unknown",PROPER(TRIM(Raw_Data!B10))) -> Unknown | C10: =IF(TRIM(Raw_Data!C10)="","South",TRIM(Raw_Data!C10)) -> East | D10: =IF(TRIM(Raw_Data!D10)="",30435.80739,Raw_Data!D10) -> 17009.59 | E10: =TEXT(Raw_Data!E10,"DD-MM-YYYY") -> 22-02-2024
A11: 1009 | B11: =IF(TRIM(Raw_Data!B11)="","Unknown",PROPER(TRIM(Raw_Data!B11))) -> Tablet | C11: =IF(TRIM(Raw_Data!C11)="","South",TRIM(Raw_Data!C11)) -> West | D11: =IF(TRIM(Raw_Data!D11)="",30435.80739,Raw_Data!D11) -> 1922.55 | E11: =TEXT(Raw_Data!E11,"DD-MM-YYYY") -> 09-01-2024
A12: 1542 | B12: =IF(TRIM(Raw_Data!B12)="","Unknown",PROPER(TRIM(Raw_Data!B12))) -> Keyboard | C12: =IF(TRIM(Raw_Data!C12)="","South",TRIM(Raw_Data!C12)) -> North | D12: =IF(TRIM(Raw_Data!D12)="",30435.80739,Raw_Data!D12) -> 46504.95 | E12: =TEXT(Raw_Data!E12,"DD-MM-YYYY") -> 17-09-2024
A13: 1011 | B13: =IF(TRIM(Raw_Data!B13)="","Unknown",PROPER(TRIM(Raw_Data!B13))) -> Laptop | C13: =IF(TRIM(Raw_Data!C13)="","South",TRIM(Raw_Data!C13)) -> North | D13: =IF(TRIM(Raw_Data!D13)="",30435.80739,Raw_Data!D13) -> 22878.28 | E13: =TEXT(Raw_Data!E13,"DD-MM-YYYY") -> 02-03-2024
... A1201: 2199 | B1201: =IF(TRIM(Raw_Data!B1201)="","Unknown",PROPER(TRIM(Raw_Data!B1201))) -> Tablet | C1201: =IF(TRIM(Raw_Data!C1201)="","South",TRIM(Raw_Data!C1201)) -> West | D1201: =IF(TRIM(Raw_Data!D1201)="",30435.80739,Raw_Data!D1201) -> 3647.98 | E1201: =TEXT(Raw_Data!E1201,"DD-MM-YYYY") -> 06-02-2024

Sheet Data_Analysis
A1: TOTAL SALES | B1: =SUM(Cleaned_Data!D:D) -> 36522969
A3: Region | B3: Count of Region | K3: Products | L3: Sum of Revenue
A4: East | B4: 275 | K4: Keyboard | L4: 6509041.1
A5: North | B5: 292 | K5: Laptop | L5: 6579854.8
A6: South | B6: 344 | K6: Monitor | L6: 6531293.3
A7: West | B7: 289 | K7: Mouse | L7: 7333008.5
A8: Grand Total | B8: 1200 | K8: Tablet | L8: 7450700.6
K9: Unknown | L9: 2119070.5
K10: Grand Total | L10: 36522969
